Workbook

Sheet Касса
B1: наличные | C1: рубли | D1: бн | E1: яндекс | F1: кр код | G1: общая
A2: 1 | B2: 3879 | C2: 18987 | D2: 242186 | E2: 2928 | G2: 267980
A3: 2 | B3: 210 | C3: 28357 | D3: 144207 | F3: 5590 | G3: 178364
A4: 3 | B4: 370 | C4: 12640 | D4: 166992 | E4: 5600 | G4: 185602
A5: 4 | B5: 500 | C5: 36322 | D5: 124934 | E5: 1912 | F5: 2460 | G5: 166128
A6: 5 | B6: 1720 | C6: 33663 | D6: 128216 | E6: 2144 | F6: 14946 | G6: 184473
A7: 6 | B7: 280 | C7: 33213 | D7: 144552 | E7: 3768 | G7: 181813
A8: 7 | B8: 1870 | C8: 38560 | D8: 149608 | E8: 4440 | G8: 194478
A9: 8 | B9: 11495 | C9: 52204 | D9: 202745 | F9: 4440 | G9: 270884
A10: 9 | B10: 4350 | C10: 42430 | D10: 127582 | F10: 3370 | G10: 177732
A11: 10 | B11: 1710 | C11: 14653 | D11: 130430 | G11: 146793
A12: 11 | B12: 2356 | C12: 74062 | D12: 76412 | F12: 798 | G12: 163628
A13: 12 | B13: 2000 | C13: 36724 | D13: 89806 | E13: 4000 | F13: 2590 | G13: 135120
A14: 13 | B14: 689 | C14: 30777 | D14: 140578 | G14: 172044
A15: 14 | B15: 1573 | C15: 16895 | D15: 147987 | F15: 4750 | G15: 171205
A16: 15 | B16: 8235 | C16: 45881 | D16: 140883 | E16: 1456 | F16: 456 | G16: 196911
A17: 16 | B17: 2700 | C17: 20238 | D17: 100513 | G17: 123451
A18: 17 | B18: 280 | C18: 41550 | D18: 122065 | E18: 2568 | G18: 166463
A19: 18 | B19: 345 | C19: 35301 | D19: 77495 | E19: 8440 | G19: 121581
A20: 19 | B20: 3080 | C20: 38260 | D20: 131292 | E20: 432 | F20: 9100 | G20: 182164
A21: 20 | B21: 1000 | C21: 36950 | D21: 102502 | E21: 2320 | F21: 4490 | G21: 147262
A22: 21 | B22: 2270 | C22: 50220 | D22: 72700 | E22: 3528 | F22: 3160 | G22: 131878
A23: 22 | B23: 1050 | C23: 15522 | D23: 114123 | G23: 130695
A24: 23 | B24: 11710 | C24: 3469 | D24: 159631 | F24: 1764 | G24: 197795
A25: 24 | C25: 19290 | D25: 103338 | E25: 1616 | G25: 124244
A26: 25 | B26: 730 | C26: 42396 | D26: 111713 | E26: 864 | G26: 155703
A27: 26
A28: 27
A29: 28
A30: 29
A31: 30
A32: 31
G349: =G348+#REF!-F349 -> #REF!
G350: =G349+#REF!-F350 -> #REF!
G351: =G350+#REF!-F351 -> #REF!
G352: =G351+#REF!-F352 -> #REF!
G353: =G352+#REF!-F353 -> #REF!
G354: =G353+#REF!-F354 -> #REF!
G355: =G354+#REF!-F355 -> #REF!
G356: =G355+#REF!-F356 -> #REF!
...

Sheet Расход
A2: Дата | B2: Закуп | D2: зп | F2: оплата поставщики | H2: маркетинг | J2: связь, интерет | L2: посуда | N2: МБП зал | P2: форма | R2: Полиграфия | T2: доставка | V2: Услуги контрагентов | X2: сервис | Z2: призы | AB2: чай | AD2: Покупка оборудования | AF2: Ремонт оборудования | AH2: Коммунальные услуги | AJ2: Аренда жилья | AL2: крыша | AN2: Развлекательная программа | AP2: аренда | AR2: декор | AT2: аптека | AV2: Итого ДЕНЬ
B3: Сумма | C3: Комментарий | D3: Сумма | E3: Комментарий | F3: Сумма | G3: Комментарий | H3: Сумма | I3: Комментарий | L3: Сумма | M3: Комментарий | N3: Сумма | O3: Комментарий | P3: Сумма | Q3: Комментарий | R3: Сумма | S3: Комментарий | T3: Сумма | U3: Комментарий | V3: Сумма | W3: Комментарий | X3: Сумма | Y3: Комментарий | Z3: Сумма | AA3: Комментарий | AD3: Сумма | AE3: Комментарий | AF3: Сумма | AG3: Комментарий | AH3: Сумма | AI3: Комментарий | AJ3: Сумма | AK3: Комментарий | AL3: Сумма | AM3: Комментарий | AN3: Сумма | AO3: Комментарий | AP3: Сумма | AQ3: Комментарий | AR3: Сумма | AS3: % | AT3: Сумма | AU3: Комментарий
B4: 1034 | D4: 3000 | F4: 12800 | H4: 1500 | J4: 5900 | N4: 10009 | P4: 18000 | T4: 1200 | V4: 32000 | W4: фискальник | X4: 8016 | AB4: 6000 | AD4: 10600 | AE4: монтаж индукции | AF4: 2632 | AH4: 50432 | AJ4: 20000 | AL4: 15000 | AN4: 4500 | AP4: 380000 | AR4: 1000 | AT4: 3000 | AV4: =X4+Z4+AD4+AF4+AH4+AJ4+AL4+AN4+AP4+#REF!+AR4+AT4 -> #REF!
B5: 1509 | D5: 4000 | E5: стажер | F5: 1800 | H5: 15000 | N5: 2756 | T5: 350 | V5: 2500 | X5: 5395 | AB5: 180 | AD5: 9864 | AE5: монтаж индукция | AF5: 1210 | AN5: 4500 | AR5: 6000 | AV5: =X5+Z5+AD5+AF5+AH5+AJ5+AL5+AN5+AP5+#REF!+AR5+AT5 -> #REF!
B6: 9800 | D6: 69000 | E6: джан расчет | F6: 2100 | H6: 20000 | N6: 4000 | O6: стирка штор | T6: 200 | V6: 3000 | X6: 5550 | AB6: 1080 | AD6: 5433 | AE6: доставка | AF6: 1040 | AN6: 4500 | AV6: =X6+Z6+AD6+AF6+AH6+AJ6+AL6+AN6+AP6+#REF!+AR6+AT6 -> #REF!
B7: 5806 | D7: 67500 | E7: наргиз | F7: 2158 | H7: 10000 | N7: 6922 | T7: 400 | V7: 35000 | W7: юля | X7: 5000 | AB7: 450 | AF7: 4000 | AN7: 4500 | AV7: =X7+Z7+AD7+AF7+AH7+AJ7+AL7+AN7+AP7+#REF!+AR7+AT7 -> #REF!
B8: 3003 | D8: 118300 | E8: иза | F8: 150000 | H8: 5000 | N8: 9953 | T8: 200 | X8: 5534 | AB8: 990 | AF8: 2025 | AN8: 4500 | AV8: =X8+Z8+AD8+AF8+AH8+AJ8+AL8+AN8+AP8+#REF!+AR8+AT8 -> #REF!
B9: 3950 | D9: 56200 | E9: коля | F9: 150000 | H9: 12000 | I9: таргет | T9: 300 | X9: 5454 | AB9: 810 | AF9: 1020 | AN9: 24000 | AV9: =X9+Z9+AD9+AF9+AH9+AJ9+AL9+AN9+AP9+#REF!+AR9+AT9 -> #REF!
B10: 1300 | D10: 5000 | E10: дима зп | H10: 10000 | I10: таргет | T10: 300 | X10: 5850 | AB10: 450 | AF10: 110 | AN10: 4500 | AV10: =X10+Z10+AD10+AF10+AH10+AJ10+AL10+AN10+AP10+#REF!+AR10+AT10 -> #REF!
B11: 1580 | D11: 30000 | E11: дима аванс | H11: 5000 | I11: вк | T11: 500 | X11: 8126 | AB11: 1170 | AF11: 4000 | AN11: 4500 | AV11: =X11+Z11+AD11+AF11+AH11+AJ11+AL11+AN11+AP11+#REF!+AR11+AT11 -> #REF!
B12: 2442 | D12: 12000 | E12: Ваня | H12: 33500 | T12: 250 | X12: 4403 | AB12: 2250 | AF12: 2361 | AN12: 4500 | AV12: =X12+Z12+AD12+AF12+AH12+AJ12+AL12+AN14+AP12+#REF!+AR12+AT12 -> #REF!
B13: 1920 | D13: 59040 | E13: настя оф | H13: 37500 | T13: 500 | X13: 4900 | AB13: 700 | AF13: 390 | AV13: =X13+Z13+AD13+AF13+AH13+AJ13+AL13+AN13+AP13+#REF!+AR13+AT13 -> #REF!
B14: 1200 | D14: 90000 | E14: иван зп | T14: 350 | X14: 4050 | AB14: 540 | AF14: 200 | AV14: =X14+Z14+AD14+AF14+AH14+AJ14+AL14+AN14+AP14+#REF!+AR14+AT14 -> #REF!
B15: 1179 | D15: 63000 | E15: катя зп | T15: 500 | X15: 5161 | AB15: 2700 | AF15: 400 | AV15: =X15+Z15+AD15+AF15+AH15+AJ15+AL15+AN15+AP15+#REF!+AR15+AT15 -> #REF!
B16: 1599 | D16: 121300 | E16: влад | X16: 5136 | AB16: 1800 | AF16: 4000 | AV16: =X16+Z16+AD16+AF16+AH16+AJ16+AL16+AN16+AP16+#REF!+AR16+AT16 -> #REF!
B17: 209 | D17: 74300 | E17: арина | X17: 5900 | AB17: 2250 | AF17: 1000 | AV17: =X17+Z17+AD17+AF17+AH17+AJ17+AL17+AN17+AP17+#REF!+AR17+AT17 -> #REF!
B18: 389 | D18: 25000 | E18: николай аванс бар | X18: 3700 | AB18: 700 | AV18: =X18+Z18+AD18+AF18+AH18+AJ18+AL18+AN18+AP18+#REF!+AR18+AT18 -> #REF!
B19: 2589 | D19: 64100 | E19: даша | X19: 4993 | AB19: 540 | AV19: =X19+Z19+AD19+AF19+AH19+AJ19+AL19+AN19+AP19+#REF!+AR19+AT19 -> #REF!
B20: 1661 | D20: 21800 | E20: коля | X20: 3647 | AB20: 1260 | AV20: =X20+Z20+AD20+AF20+AH20+AJ20+AL20+AN20+AP20+#REF!+AR20+AT20 -> #REF!
B21: 1580 | D21: 121500 | E21: андрей | X21: 5450 | AB21: 400 | AV21: =X21+Z21+AD21+AF21+AH21+AJ21+AL21+AN21+AP21+#REF!+AR21+AT21 -> #REF!
B22: 1145 | D22: 49000 | E22: наргиз расчет | X22: 4400 | AB22: 1100 | AV22: =X22+Z22+AD22+AF22+AH22+AJ22+AL22+AN22+AP22+#REF!+AR22+AT22 -> #REF!
B23: 1219 | D23: 9000 | E23: арина отзывы | X23: 3956 | AB23: 1100 | AV23: =X23+Z23+AD23+AF23+AH23+AJ23+AL23+AN23+AP23+#REF!+AR23+AT23 -> #REF!
B24: 2160 | D24: 3000 | E24: настя отзывы | X24: 3920 | AB24: 450 | AV24: =X24+Z24+AD24+AF24+AH24+AJ24+AL24+AN24+AP24+#REF!+AR24+AT24 -> #REF!
B25: 479 | D25: 20000 | E25: иза аванс | X25: 5933 | AB25: 600 | AV25: =X25+Z25+AD25+AF25+AH25+AJ25+AL25+AN25+AP25+#REF!+AR25+AT25 -> #REF!
B26: 1700 | D26: 20000 | E26: катя аванс | X26: 3700 | AB26: 1000 | AV26: =X26+Z26+AD26+AF26+AH26+AJ26+AL26+AN26+AP26+#REF!+AR26+AT26 -> #REF!
B27: 1269 | D27: 80000 | E27: иван аванс | X27: 4700 | AV27: =X27+Z27+AD27+AF27+AH27+AJ27+AL27+AN27+AP27+#REF!+AR27+AT27 -> #REF!
A28: 25 | B28: 1161 | D28: 40000 | E28: ольга аванс | AV28: =X28+Z28+AD28+AF28+AH28+AJ28+AL28+AN28+AP28+#REF!+AR28+AT28 -> #REF!
A29: 26 | D29: 60000 | E29: дима аванс | AV29: =X29+Z29+AD29+AF29+AH29+AJ29+AL29+AN29+AP29+#REF!+AR29+AT29 -> #REF!
A30: 27 | D30: 20000 | E30: аванс клининг | AV30: =X30+Z30+AD30+AF30+AH30+AJ30+AL30+AN30+AP30+#REF!+AR30+AT30 -> #REF!
A31: 28 | AV31: =X31+Z31+AD31+AF31+AH31+AJ31+AL31+AN31+AP31+#REF!+AR31+AT31 -> #REF!
A32: 29 | AV32: =X32+Z32+AD32+AF32+AH32+AJ32+AL32+AN32+AP32+#REF!+AR32+AT32 -> #REF!
A33: 30 | AV33: =X33+Z33+AD33+AF33+AH33+AJ33+AL33+AN33+AP33+#REF!+AR33+AT33 -> #REF!
AV34: =X34+Z34+AD34+AF34+AH34+AJ34+AL34+AN34+AP34+#REF!+AR34+AT34 -> #REF!
AV35: =X35+Z35+AD35+AF35+AH35+AJ35+AL35+AN35+AP35+#REF!+AR35+AT35 -> #REF!
AV36: =X36+Z36+AD36+AF36+AH36+AJ36+AL36+AN36+AP36+#REF!+AR36+AT36 -> #REF!
A37: 31 | AV37: =X37+Z37+AD37+AF37+AH37+AJ37+AL37+AN37+AP37+#REF!+AR37+AT37 -> #REF!
A38: Итого | H38: =H17+H16+H15+H14+H13+H12+H11+H10+H9+H8+H7+H6+H5+H4 -> 149500 | K38: =SUM(K4:K37) -> 0 | L38: =SUM(L4:L37) -> 0 | M38: =SUM(M4:M37) -> 0 | N38: =SUM(N4:N37) -> 33640 | O38: =SUM(O4:O37) -> 0 | P38: =SUM(P4:P37) -> 18000 | Q38: =SUM(Q4:Q37) -> 0 | R38: =SUM(R4:R37) -> 0 | ... AT38: =SUM(AT4:AT37) -> 3000 | AU38: Итого ТРАКТИР | AV38: =SUM(B38:AT38) -> 1015801
A40: ВСЕГО | B40: =B31+B30+B29+B28+B27+B26+B25+B24+B23+B22+B21+B20+B19+B18+B17+B16+B15+B14+B13+B12+B11+B10+B9+B8+B7+B6+B5+B4 -> 51883 | D40: =D37+D36+D35+D34+D33+D32+D31+D30+D29+D28+D27+D26+D25+D24+D23+D22+D21+D20+D19+D18+D17+D16+D15+D14+D13+D12+D11+D10+D9+D8+D7+D6+D5+D4 -> 1306040 | F40: =F9+F8+F7+F6+F5+F4 -> 318858 | G40: =G9+G8+G7+G6+G5+G4 -> 0 | H40: =H38 -> 149500 | J40: =J9+J8+J7+J6+J5+J4 -> 5900 | N40: =N11+N10+N9+N8+N7+N6+N5+N4 -> 33640 | P40: =P5+P4 -> 18000 | R40: =R5+R4 -> 0 | T40: =T20+T19+T18+T17+T16+T15+T14+T13+T12+T11+T10+T9+T8+T7+T6+T5+T4 -> 5050 | V40: =V38 -> 72500 | X40: =X38 -> 122874 | AB40: =AB38 -> 28520 | AD40: =AD38 -> 25897 | AF40: =AF38 -> 24388 | AH40: =AH6+AH5+AH4 -> 50432 | AJ40: =AJ5+AJ4 -> 20000 | AN40: =AN38 -> 60000 | AP40: =AP38 -> 380000 | AR40: =AR6+AR5+AR4 -> 7000 | AT40: =AT38 -> 3000 | AV40: =AV38+#REF!+#REF! -> #REF!

Sheet Сводная
K1: ь
A2: туман | F2: Баланс | K2: 1652106
A3: Выручка КУХНЯ | B3: 1413947 | C3: 0.27 | F3: Активы
A4: Выручка бар ба | B4: 845749 | C4: 0.12
A5: Выручка БАР | B5: 1519806 | C5: 0.24 | F5: склад бар | G5: 778784 | H5: средний чек | I5: 3955
A6: Выручка Кальян | B6: 2193270 | C6: 0.35 | F6: склад кухня | G6: 291866 | H6: чеков | I6: 1509
A7: Выручка | B7: =B6+B5+B4+B3 -> 5972772 | F7: склад табак | G7: 262040 | H7: скидки | I7: 444021
A8: Расход кухня | B8: 358225 | C8: 0.25
A9: Расход бар б/а | B9: 125211 | C9: 0.17
A10: Расход бар алко | B10: 398147 | C10: 0.26
A11: Расход кальян | B11: 316725 | C11: 0.14
A12: Рабочее питание | B12: 74300 | C12: 0.14
A13: Отработка блюд\смм/фото | B13: 2660 | C13: 0.14
A14: Порча, списание КУХНЯ | B14: 46000 | C14: =B14/B6 -> 0.02097325 | H14: питание учредители
A15: Порча, списание БАР | B15: 24300 | C15: =B15/B7 -> 0.0040684627 | H15: сергей | I15: 12131
A16: Комплименты | B16: 14514 | C16: =B16/B10 -> 0.036453873 | H16: сусанна | I16: 23062
A17: Расход | B17: =B18+B20+B21+B22+B23+B24+B26+B27+B28+B29+B30+B31+B32+B33+B34+B35+B36+B37+B38+B2+9+B40+B42+B43+B19+B41+B25+B39 -> 2695491 | C17: =B17/B7 -> 0.45129648 | H17: тимур | I17: 32387
A18: Закуп | B18: =Расход!B40 -> 51883 | C18: =B18/B7 -> 0.0086865864 | H18: Иван | I18: 8919
A19: доставка | B19: =Расход!T40 -> 5050 | C19: =B19/B8 -> 0.014097285
A20: зп | B20: =Расход!D40 -> 1306040 | C20: =B20/B7 -> 0.21866564 | H20: смм
A21: оплата поставщики | B21: =Расход!F40 -> 318858 | C21: =B21/B10 -> 0.80085496 | H21: фирма | I21: 20004
A22: услуги контрагентов | B22: =Расход!V40 -> 72500 | C22: =B22/B7 -> 0.012138417
A23: Цветы и декор | B23: =Расход!AR40 -> 7000 | C23: =B23/B7 -> 0.0011719851
A24: МБП зал | B24: =Расход!N40 -> 33640 | C24: =B24/B7 -> 0.0056322257
A25: чай | B25: =Расход!AB40 -> 28520 | C25: =B25/B8 -> 0.079614767
A26: Связь интернет | B26: =Расход!J40 -> 5900 | C26: =B26/B7 -> 0.00098781604
A27: Полиграфия | B27: =Расход!R40 -> 0 | C27: ъ
A28: развлекательная программа | B28: =Расход!AN40 -> 60000 | C28: =B28/B7 -> 0.010045587
A29: форма | B29: =Расход!P40 -> 18000 | C29: =B29/B7 -> 0.0030136761 | F29: Итого Активы | G29: =SUM(G5:G28) -> 1332690
A30: Покупка оборудования | B30: =Расход!AD40 -> 25897 | C30: =B30/B7 -> 0.0043358427 | F30: Пассивы
A31: Ремонт оборудования | B31: =Расход!AF40 -> 24388 | C31: =B31/B8 -> 0.068080117 | F31: долги поставщики | G31: 621340
A32: Коммунальные расходы | B32: =Расход!AH40 -> 50432 | C32: =B32/B7 -> 0.0084436506 | F32: зп | G32: 907000
A33: Аренда жилья | B33: =Расход!AJ4 -> 20000 | C33: =B33/B7 -> 0.003348529
A34: Крыша | B34: =Расход!AL38 -> 15000 | C34: =B34/B7 -> 0.0025113967
A35: маркетинг | B35: =Расход!H40 -> 149500 | C35: =B35/B7 -> 0.025030254
A36: Услуги эквайринга | C36: =B36/B7 -> 0
A37: сервис | B37: =Расход!X40 -> 122874 | C37: =B37/B7 -> 0.020572357
A38: Аренда | B38: =Расход!AP40 -> 380000 | C38: =B38/B10 -> 0.95442136
A39: хозы оплачено
A40: налоги | C40: =B40/B12 -> 0 | F40: Итого Пассивы | G40: =SUM(G31:G39) -> 1528340
...

Sheet зп
B1: Влад КМ | D1: Андрей КМ | F1: Коля | H1: Катя | J1: Иван | L1: Арина | N1: Даша | P1: Анастасия | R1: Коля | T1: Иза | V1: Дима | W1: Джан | Z1: Наргиз
A3: 1
A4: 2
A5: 3
A6: 1
A7: 5
A8: 6
A9: 7
A10: 8
A11: 9
A12: 10
A13: 11
A14: 12
... A17: 15
A18: 16 | AD18: =
A19: 17
A20: 18
A21: 19
A22: 20
A23: 21
A24: 22
A25: 23
A26: 24
A27: 25
A28: 26
A29: 27
A30: 28
A31: 29
A32: 30 | B32: 14 | C32: 4 | D32: 14 | F32: 13 | H32: 15 | J32: 20 | L32: 13.5 | N32: 12 | P32: 11.5 | R32: 4.5 | T32: 22 | V32: 17
A33: 31 | B33: 14000 | D33: 14000 | F33: 45500 | H33: 52500 | J33: 165000 | L33: 51320 | N33: 44000 | P33: 39840 | R33: 14200 | T33: 121000 | V33: 93500 | W33: 12500
B34: 109650 | D34: 109650 | F34: 43178 | H34: 51000 | L34: 29700 | N34: 21600 | P34: 20700 | R34: 8100 | T34: 27280 | W34: 104500
B36: =B34+B33 -> 123650 | C36: =C34+C33 -> 0 | D36: =D34+D33 -> 123650 | E36: =E34+E33 -> 0 | F36: =F34+F33 -> 88678 | G36: =G34+G33 -> 0 | H36: =H34+H33 -> 103500 | I36: =I34+I33 -> 0 | J36: 175000 | K36: =K34+K33 -> 0 | L36: 79800 | M36: =M34+M33 -> 0 | N36: =N34+N33 -> 65600 | O36: =O34+O33 -> 0 | P36: =P34+P33 -> 60540 | Q36: =Q34+Q33 -> 0 | R36: =R34+R33 -> 22300 | T36: =T33+T34 -> 148280 | V36: 99500 | W36: =W34+W33 -> 117000 | Z36: 94500 | AB36: 1296218
B37: 0 | D37: 0 | F37: 20000 | H37: 30000 | J37: 85000 | L37: 4000 | Z37: 30000
F38: 4000 | H38: 2500 | L38: 1500 | N38: 1500 | P38: 1500 | R38: 500 | T38: 30000 | W38: 76000
F39: 1000 | H39: 1000 | Z39: 3000
B40: =B36 -> 123650 | D40: =D36 -> 123650 | F40: =F36-F37-F38-F39 -> 63678 | H40: =H36-H37-H38-H39 -> 70000 | J40: =J36-J37 -> 90000 | L40: =L36-L37-L38 -> 74300 | N40: =N36-N38 -> 64100 | P40: =P36-P38 -> 59040 | R40: =R36-R38 -> 21800 | T40: =T36-T38 -> 118280 | V40: 4500 | W40: =W36-W38 -> 41000 | Z40: =Z36-Z37 -> 64500 | AB40: 907000
F41: =F40-7500 -> 56178 | H41: 7500
H42: =H40-H41 -> 62500
